java.net.ConnectException: Call From anmol-vm1-new/10.0.1.190 to anmol-vm1-new:8020 failed on connection exception: java.net.ConnectException: Connection refused; For more details see:  http://wiki.apache.org/hadoop/ConnectionRefused
	at sun.reflect.NativeConstructorAccessorImpl.newInstance0(Native Method)
	at sun.reflect.NativeConstructorAccessorImpl.newInstance(NativeConstructorAccessorImpl.java:57)
	at sun.reflect.DelegatingConstructorAccessorImpl.newInstance(DelegatingConstructorAccessorImpl.java:45)
	at java.lang.reflect.Constructor.newInstance(Constructor.java:526)
	at org.apache.hadoop.net.NetUtils.wrapWithMessage(NetUtils.java:783)
	at org.apache.hadoop.net.NetUtils.wrapException(NetUtils.java:730)
	at org.apache.hadoop.ipc.Client.call(Client.java:1415)
	at org.apache.hadoop.ipc.Client.call(Client.java:1364)
	at org.apache.hadoop.ipc.ProtobufRpcEngine$Invoker.invoke(ProtobufRpcEngine.java:206)
	at com.sun.proxy.$Proxy9.getTransactionId(Unknown Source)
	at sun.reflect.NativeMethodAccessorImpl.invoke0(Native Method)
	at sun.reflect.NativeMethodAccessorImpl.invoke(NativeMethodAccessorImpl.java:57)
	at sun.reflect.DelegatingMethodAccessorImpl.invoke(DelegatingMethodAccessorImpl.java:43)
	at java.lang.reflect.Method.invoke(Method.java:606)
	at org.apache.hadoop.io.retry.RetryInvocationHandler.invokeMethod(RetryInvocationHandler.java:190)
	at org.apache.hadoop.io.retry.RetryInvocationHandler.invoke(RetryInvocationHandler.java:103)
	at com.sun.proxy.$Proxy9.getTransactionId(Unknown Source)
	at org.apache.hadoop.hdfs.protocolPB.NamenodeProtocolTranslatorPB.getTransactionID(NamenodeProtocolTranslatorPB.java:119)
	at org.apache.hadoop.hdfs.server.namenode.SecondaryNameNode.countUncheckpointedTxns(SecondaryNameNode.java:621)
	at org.apache.hadoop.hdfs.server.namenode.SecondaryNameNode.shouldCheckpointBasedOnCount(SecondaryNameNode.java:629)
	at org.apache.hadoop.hdfs.server.namenode.SecondaryNameNode.doWork(SecondaryNameNode.java:381)
	at org.apache.hadoop.hdfs.server.namenode.SecondaryNameNode$1.run(SecondaryNameNode.java:349)
	at org.apache.hadoop.security.SecurityUtil.doAsLoginUserOrFatal(SecurityUtil.java:415)
	at org.apache.hadoop.hdfs.server.namenode.SecondaryNameNode.run(SecondaryNameNode.java:345)
	at java.lang.Thread.run(Thread.java:745)
Caused by: java.net.ConnectException: Connection refused
	at sun.nio.ch.SocketChannelImpl.checkConnect(Native Method)
	at sun.nio.ch.SocketChannelImpl.finishConnect(SocketChannelImpl.java:744)
	at org.apache.hadoop.net.SocketIOWithTimeout.connect(SocketIOWithTimeout.java:206)
	at org.apache.hadoop.net.NetUtils.connect(NetUtils.java:529)
	at org.apache.hadoop.net.NetUtils.connect(NetUtils.java:493)
	at org.apache.hadoop.ipc.Client$Connection.setupConnection(Client.java:605)
	at org.apache.hadoop.ipc.Client$Connection.setupIOstreams(Client.java:700)
	at org.apache.hadoop.ipc.Client$Connection.access$2800(Client.java:367)
	at org.apache.hadoop.ipc.Client.getConnection(Client.java:1463)
	at org.apache.hadoop.ipc.Client.call(Client.java:1382)
	... 18 more
java.net.ConnectException: Call From anmol-vm1-new/10.0.1.190 to anmol-vm1-new:8020 failed on connection exception: java.net.ConnectException: Connection refused; For more details see:  http://wiki.apache.org/hadoop/ConnectionRefused
	at sun.reflect.NativeConstructorAccessorImpl.newInstance0(Native Method)
	at sun.reflect.NativeConstructorAccessorImpl.newInstance(NativeConstructorAccessorImpl.java:57)
	at sun.reflect.DelegatingConstructorAccessorImpl.newInstance(DelegatingConstructorAccessorImpl.java:45)
	at java.lang.reflect.Constructor.newInstance(Constructor.java:526)
	at org.apache.hadoop.net.NetUtils.wrapWithMessage(NetUtils.java:783)
	at org.apache.hadoop.net.NetUtils.wrapException(NetUtils.java:730)
	at org.apache.hadoop.ipc.Client.call(Client.java:1415)
	at org.apache.hadoop.ipc.Client.call(Client.java:1364)
	at org.apache.hadoop.ipc.ProtobufRpcEngine$Invoker.invoke(ProtobufRpcEngine.java:206)
	at com.sun.proxy.$Proxy9.getTransactionId(Unknown Source)
	at sun.reflect.NativeMethodAccessorImpl.invoke0(Native Method)
	at sun.reflect.NativeMethodAccessorImpl.invoke(NativeMethodAccessorImpl.java:57)
	at sun.reflect.DelegatingMethodAccessorImpl.invoke(DelegatingMethodAccessorImpl.java:43)
	at java.lang.reflect.Method.invoke(Method.java:606)
	at org.apache.hadoop.io.retry.RetryInvocationHandler.invokeMethod(RetryInvocationHandler.java:190)
	at org.apache.hadoop.io.retry.RetryInvocationHandler.invoke(RetryInvocationHandler.java:103)
	at com.sun.proxy.$Proxy9.getTransactionId(Unknown Source)
	at org.apache.hadoop.hdfs.protocolPB.NamenodeProtocolTranslatorPB.getTransactionID(NamenodeProtocolTranslatorPB.java:119)
	at org.apache.hadoop.hdfs.server.namenode.SecondaryNameNode.countUncheckpointedTxns(SecondaryNameNode.java:621)
	at org.apache.hadoop.hdfs.server.namenode.SecondaryNameNode.shouldCheckpointBasedOnCount(SecondaryNameNode.java:629)
	at org.apache.hadoop.hdfs.server.namenode.SecondaryNameNode.doWork(SecondaryNameNode.java:381)
	at org.apache.hadoop.hdfs.server.namenode.SecondaryNameNode$1.run(SecondaryNameNode.java:349)
	at org.apache.hadoop.security.SecurityUtil.doAsLoginUserOrFatal(SecurityUtil.java:415)
	at org.apache.hadoop.hdfs.server.namenode.SecondaryNameNode.run(SecondaryNameNode.java:345)
	at java.lang.Thread.run(Thread.java:745)
Caused by: java.net.ConnectException: Connection refused
	at sun.nio.ch.SocketChannelImpl.checkConnect(Native Method)
	at sun.nio.ch.SocketChannelImpl.finishConnect(SocketChannelImpl.java:744)
	at org.apache.hadoop.net.SocketIOWithTimeout.connect(SocketIOWithTimeout.java:206)
	at org.apache.hadoop.net.NetUtils.connect(NetUtils.java:529)
	at org.apache.hadoop.net.NetUtils.connect(NetUtils.java:493)
	at org.apache.hadoop.ipc.Client$Connection.setupConnection(Client.java:605)
	at org.apache.hadoop.ipc.Client$Connection.setupIOstreams(Client.java:700)
	at org.apache.hadoop.ipc.Client$Connection.access$2800(Client.java:367)
	at org.apache.hadoop.ipc.Client.getConnection(Client.java:1463)
	at org.apache.hadoop.ipc.Client.call(Client.java:1382)
	... 18 more
java.net.ConnectException: Call From anmol-vm1-new/10.0.1.190 to anmol-vm1-new:8020 failed on connection exception: java.net.ConnectException: Connection refused; For more details see:  http://wiki.apache.org/hadoop/ConnectionRefused
	at sun.reflect.NativeConstructorAccessorImpl.newInstance0(Native Method)
	at sun.reflect.NativeConstructorAccessorImpl.newInstance(NativeConstructorAccessorImpl.java:57)
	at sun.reflect.DelegatingConstructorAccessorImpl.newInstance(DelegatingConstructorAccessorImpl.java:45)
	at java.lang.reflect.Constructor.newInstance(Constructor.java:526)
	at org.apache.hadoop.net.NetUtils.wrapWithMessage(NetUtils.java:783)
	at org.apache.hadoop.net.NetUtils.wrapException(NetUtils.java:730)
	at org.apache.hadoop.ipc.Client.call(Client.java:1415)
	at org.apache.hadoop.ipc.Client.call(Client.java:1364)
	at org.apache.hadoop.ipc.ProtobufRpcEngine$Invoker.invoke(ProtobufRpcEngine.java:206)
	at com.sun.proxy.$Proxy9.getTransactionId(Unknown Source)
	at sun.reflect.NativeMethodAccessorImpl.invoke0(Native Method)
	at sun.reflect.NativeMethodAccessorImpl.invoke(NativeMethodAccessorImpl.java:57)
	at sun.reflect.DelegatingMethodAccessorImpl.invoke(DelegatingMethodAccessorImpl.java:43)
	at java.lang.reflect.Method.invoke(Method.java:606)
	at org.apache.hadoop.io.retry.RetryInvocationHandler.invokeMethod(RetryInvocationHandler.java:190)
	at org.apache.hadoop.io.retry.RetryInvocationHandler.invoke(RetryInvocationHandler.java:103)
	at com.sun.proxy.$Proxy9.getTransactionId(Unknown Source)
	at org.apache.hadoop.hdfs.protocolPB.NamenodeProtocolTranslatorPB.getTransactionID(NamenodeProtocolTranslatorPB.java:119)
	at org.apache.hadoop.hdfs.server.namenode.SecondaryNameNode.countUncheckpointedTxns(SecondaryNameNode.java:621)
	at org.apache.hadoop.hdfs.server.namenode.SecondaryNameNode.shouldCheckpointBasedOnCount(SecondaryNameNode.java:629)
	at org.apache.hadoop.hdfs.server.namenode.SecondaryNameNode.doWork(SecondaryNameNode.java:381)
	at org.apache.hadoop.hdfs.server.namenode.SecondaryNameNode$1.run(SecondaryNameNode.java:349)
	at org.apache.hadoop.security.SecurityUtil.doAsLoginUserOrFatal(SecurityUtil.java:415)
	at org.apache.hadoop.hdfs.server.namenode.SecondaryNameNode.run(SecondaryNameNode.java:345)
	at java.lang.Thread.run(Thread.java:745)
Caused by: java.net.ConnectException: Connection refused
	at sun.nio.ch.SocketChannelImpl.checkConnect(Native Method)
	at sun.nio.ch.SocketChannelImpl.finishConnect(SocketChannelImpl.java:744)
	at org.apache.hadoop.net.SocketIOWithTimeout.connect(SocketIOWithTimeout.java:206)
	at org.apache.hadoop.net.NetUtils.connect(NetUtils.java:529)
	at org.apache.hadoop.net.NetUtils.connect(NetUtils.java:493)
	at org.apache.hadoop.ipc.Client$Connection.setupConnection(Client.java:605)
	at org.apache.hadoop.ipc.Client$Connection.setupIOstreams(Client.java:700)
	at org.apache.hadoop.ipc.Client$Connection.access$2800(Client.java:367)
	at org.apache.hadoop.ipc.Client.getConnection(Client.java:1463)
	at org.apache.hadoop.ipc.Client.call(Client.java:1382)
	... 18 more
java.net.ConnectException: Call From anmol-vm1-new/10.0.1.190 to anmol-vm1-new:8020 failed on connection exception: java.net.ConnectException: Connection refused; For more details see:  http://wiki.apache.org/hadoop/ConnectionRefused
	at sun.reflect.NativeConstructorAccessorImpl.newInstance0(Native Method)
	at sun.reflect.NativeConstructorAccessorImpl.newInstance(NativeConstructorAccessorImpl.java:57)
	at sun.reflect.DelegatingConstructorAccessorImpl.newInstance(DelegatingConstructorAccessorImpl.java:45)
	at java.lang.reflect.Constructor.newInstance(Constructor.java:526)
	at org.apache.hadoop.net.NetUtils.wrapWithMessage(NetUtils.java:783)
	at org.apache.hadoop.net.NetUtils.wrapException(NetUtils.java:730)
	at org.apache.hadoop.ipc.Client.call(Client.java:1415)
	at org.apache.hadoop.ipc.Client.call(Client.java:1364)
	at org.apache.hadoop.ipc.ProtobufRpcEngine$Invoker.invoke(ProtobufRpcEngine.java:206)
	at com.sun.proxy.$Proxy9.getTransactionId(Unknown Source)
	at sun.reflect.NativeMethodAccessorImpl.invoke0(Native Method)
	at sun.reflect.NativeMethodAccessorImpl.invoke(NativeMethodAccessorImpl.java:57)
	at sun.reflect.DelegatingMethodAccessorImpl.invoke(DelegatingMethodAccessorImpl.java:43)
	at java.lang.reflect.Method.invoke(Method.java:606)
	at org.apache.hadoop.io.retry.RetryInvocationHandler.invokeMethod(RetryInvocationHandler.java:190)
	at org.apache.hadoop.io.retry.RetryInvocationHandler.invoke(RetryInvocationHandler.java:103)
	at com.sun.proxy.$Proxy9.getTransactionId(Unknown Source)
	at org.apache.hadoop.hdfs.protocolPB.NamenodeProtocolTranslatorPB.getTransactionID(NamenodeProtocolTranslatorPB.java:119)
	at org.apache.hadoop.hdfs.server.namenode.SecondaryNameNode.countUncheckpointedTxns(SecondaryNameNode.java:621)
	at org.apache.hadoop.hdfs.server.namenode.SecondaryNameNode.shouldCheckpointBasedOnCount(SecondaryNameNode.java:629)
	at org.apache.hadoop.hdfs.server.namenode.SecondaryNameNode.doWork(SecondaryNameNode.java:381)
	at org.apache.hadoop.hdfs.server.namenode.SecondaryNameNode$1.run(SecondaryNameNode.java:349)
	at org.apache.hadoop.security.SecurityUtil.doAsLoginUserOrFatal(SecurityUtil.java:415)
	at org.apache.hadoop.hdfs.server.namenode.SecondaryNameNode.run(SecondaryNameNode.java:345)
	at java.lang.Thread.run(Thread.java:745)
Caused by: java.net.ConnectException: Connection refused
	at sun.nio.ch.SocketChannelImpl.checkConnect(Native Method)
	at sun.nio.ch.SocketChannelImpl.finishConnect(SocketChannelImpl.java:744)
	at org.apache.hadoop.net.SocketIOWithTimeout.connect(SocketIOWithTimeout.java:206)
	at org.apache.hadoop.net.NetUtils.connect(NetUtils.java:529)
	at org.apache.hadoop.net.NetUtils.connect(NetUtils.java:493)
	at org.apache.hadoop.ipc.Client$Connection.setupConnection(Client.java:605)
	at org.apache.hadoop.ipc.Client$Connection.setupIOstreams(Client.java:700)
	at org.apache.hadoop.ipc.Client$Connection.access$2800(Client.java:367)
	at org.apache.hadoop.ipc.Client.getConnection(Client.java:1463)
	at org.apache.hadoop.ipc.Client.call(Client.java:1382)
	... 18 more
java.net.ConnectException: Call From anmol-vm1-new/10.0.1.190 to anmol-vm1-new:8020 failed on connection exception: java.net.ConnectException: Connection refused; For more details see:  http://wiki.apache.org/hadoop/ConnectionRefused
	at sun.reflect.NativeConstructorAccessorImpl.newInstance0(Native Method)
	at sun.reflect.NativeConstructorAccessorImpl.newInstance(NativeConstructorAccessorImpl.java:57)
	at sun.reflect.DelegatingConstructorAccessorImpl.newInstance(DelegatingConstructorAccessorImpl.java:45)
	at java.lang.reflect.Constructor.newInstance(Constructor.java:526)
	at org.apache.hadoop.net.NetUtils.wrapWithMessage(NetUtils.java:783)
	at org.apache.hadoop.net.NetUtils.wrapException(NetUtils.java:730)
	at org.apache.hadoop.ipc.Client.call(Client.java:1415)
	at org.apache.hadoop.ipc.Client.call(Client.java:1364)
	at org.apache.hadoop.ipc.ProtobufRpcEngine$Invoker.invoke(ProtobufRpcEngine.java:206)
	at com.sun.proxy.$Proxy9.getTransactionId(Unknown Source)
	at sun.reflect.NativeMethodAccessorImpl.invoke0(Native Method)
	at sun.reflect.NativeMethodAccessorImpl.invoke(NativeMethodAccessorImpl.java:57)
	at sun.reflect.DelegatingMethodAccessorImpl.invoke(DelegatingMethodAccessorImpl.java:43)
	at java.lang.reflect.Method.invoke(Method.java:606)
	at org.apache.hadoop.io.retry.RetryInvocationHandler.invokeMethod(RetryInvocationHandler.java:190)
	at org.apache.hadoop.io.retry.RetryInvocationHandler.invoke(RetryInvocationHandler.java:103)
	at com.sun.proxy.$Proxy9.getTransactionId(Unknown Source)
	at org.apache.hadoop.hdfs.protocolPB.NamenodeProtocolTranslatorPB.getTransactionID(NamenodeProtocolTranslatorPB.java:119)
	at org.apache.hadoop.hdfs.server.namenode.SecondaryNameNode.countUncheckpointedTxns(SecondaryNameNode.java:621)
	at org.apache.hadoop.hdfs.server.namenode.SecondaryNameNode.shouldCheckpointBasedOnCount(SecondaryNameNode.java:629)
	at org.apache.hadoop.hdfs.server.namenode.SecondaryNameNode.doWork(SecondaryNameNode.java:381)
	at org.apache.hadoop.hdfs.server.namenode.SecondaryNameNode$1.run(SecondaryNameNode.java:349)
	at org.apache.hadoop.security.SecurityUtil.doAsLoginUserOrFatal(SecurityUtil.java:415)
	at org.apache.hadoop.hdfs.server.namenode.SecondaryNameNode.run(SecondaryNameNode.java:345)
	at java.lang.Thread.run(Thread.java:745)
Caused by: java.net.ConnectException: Connection refused
	at sun.nio.ch.SocketChannelImpl.checkConnect(Native Method)
	at sun.nio.ch.SocketChannelImpl.finishConnect(SocketChannelImpl.java:744)
	at org.apache.hadoop.net.SocketIOWithTimeout.connect(SocketIOWithTimeout.java:206)
	at org.apache.hadoop.net.NetUtils.connect(NetUtils.java:529)
	at org.apache.hadoop.net.NetUtils.connect(NetUtils.java:493)
	at org.apache.hadoop.ipc.Client$Connection.setupConnection(Client.java:605)
	at org.apache.hadoop.ipc.Client$Connection.setupIOstreams(Client.java:700)
	at org.apache.hadoop.ipc.Client$Connection.access$2800(Client.java:367)
	at org.apache.hadoop.ipc.Client.getConnection(Client.java:1463)
	at org.apache.hadoop.ipc.Client.call(Client.java:1382)
	... 18 more
java.net.ConnectException: Call From anmol-vm1-new/10.0.1.190 to anmol-vm1-new:8020 failed on connection exception: java.net.ConnectException: Connection refused; For more details see:  http://wiki.apache.org/hadoop/ConnectionRefused
	at sun.reflect.NativeConstructorAccessorImpl.newInstance0(Native Method)
	at sun.reflect.NativeConstructorAccessorImpl.newInstance(NativeConstructorAccessorImpl.java:57)
	at sun.reflect.DelegatingConstructorAccessorImpl.newInstance(DelegatingConstructorAccessorImpl.java:45)
	at java.lang.reflect.Constructor.newInstance(Constructor.java:526)
	at org.apache.hadoop.net.NetUtils.wrapWithMessage(NetUtils.java:783)
	at org.apache.hadoop.net.NetUtils.wrapException(NetUtils.java:730)
	at org.apache.hadoop.ipc.Client.call(Client.java:1415)
	at org.apache.hadoop.ipc.Client.call(Client.java:1364)
	at org.apache.hadoop.ipc.ProtobufRpcEngine$Invoker.invoke(ProtobufRpcEngine.java:206)
	at com.sun.proxy.$Proxy9.getTransactionId(Unknown Source)
	at sun.reflect.NativeMethodAccessorImpl.invoke0(Native Method)
	at sun.reflect.NativeMethodAccessorImpl.invoke(NativeMethodAccessorImpl.java:57)
	at sun.reflect.DelegatingMethodAccessorImpl.invoke(DelegatingMethodAccessorImpl.java:43)
	at java.lang.reflect.Method.invoke(Method.java:606)
	at org.apache.hadoop.io.retry.RetryInvocationHandler.invokeMethod(RetryInvocationHandler.java:190)
	at org.apache.hadoop.io.retry.RetryInvocationHandler.invoke(RetryInvocationHandler.java:103)
	at com.sun.proxy.$Proxy9.getTransactionId(Unknown Source)
	at org.apache.hadoop.hdfs.protocolPB.NamenodeProtocolTranslatorPB.getTransactionID(NamenodeProtocolTranslatorPB.java:119)
	at org.apache.hadoop.hdfs.server.namenode.SecondaryNameNode.countUncheckpointedTxns(SecondaryNameNode.java:621)
	at org.apache.hadoop.hdfs.server.namenode.SecondaryNameNode.shouldCheckpointBasedOnCount(SecondaryNameNode.java:629)
	at org.apache.hadoop.hdfs.server.namenode.SecondaryNameNode.doWork(SecondaryNameNode.java:381)
	at org.apache.hadoop.hdfs.server.namenode.SecondaryNameNode$1.run(SecondaryNameNode.java:349)
	at org.apache.hadoop.security.SecurityUtil.doAsLoginUserOrFatal(SecurityUtil.java:415)
	at org.apache.hadoop.hdfs.server.namenode.SecondaryNameNode.run(SecondaryNameNode.java:345)
	at java.lang.Thread.run(Thread.java:745)
Caused by: java.net.ConnectException: Connection refused
	at sun.nio.ch.SocketChannelImpl.checkConnect(Native Method)
	at sun.nio.ch.SocketChannelImpl.finishConnect(SocketChannelImpl.java:744)
	at org.apache.hadoop.net.SocketIOWithTimeout.connect(SocketIOWithTimeout.java:206)
	at org.apache.hadoop.net.NetUtils.connect(NetUtils.java:529)
	at org.apache.hadoop.net.NetUtils.connect(NetUtils.java:493)
	at org.apache.hadoop.ipc.Client$Connection.setupConnection(Client.java:605)
	at org.apache.hadoop.ipc.Client$Connection.setupIOstreams(Client.java:700)
	at org.apache.hadoop.ipc.Client$Connection.access$2800(Client.java:367)
	at org.apache.hadoop.ipc.Client.getConnection(Client.java:1463)
	at org.apache.hadoop.ipc.Client.call(Client.java:1382)
	... 18 more
java.net.ConnectException: Call From anmol-vm1-new/10.0.1.190 to anmol-vm1-new:8020 failed on connection exception: java.net.ConnectException: Connection refused; For more details see:  http://wiki.apache.org/hadoop/ConnectionRefused
	at sun.reflect.NativeConstructorAccessorImpl.newInstance0(Native Method)
	at sun.reflect.NativeConstructorAccessorImpl.newInstance(NativeConstructorAccessorImpl.java:57)
	at sun.reflect.DelegatingConstructorAccessorImpl.newInstance(DelegatingConstructorAccessorImpl.java:45)
	at java.lang.reflect.Constructor.newInstance(Constructor.java:526)
	at org.apache.hadoop.net.NetUtils.wrapWithMessage(NetUtils.java:783)
	at org.apache.hadoop.net.NetUtils.wrapException(NetUtils.java:730)
	at org.apache.hadoop.ipc.Client.call(Client.java:1415)
	at org.apache.hadoop.ipc.Client.call(Client.java:1364)
	at org.apache.hadoop.ipc.ProtobufRpcEngine$Invoker.invoke(ProtobufRpcEngine.java:206)
	at com.sun.proxy.$Proxy9.getTransactionId(Unknown Source)
	at sun.reflect.NativeMethodAccessorImpl.invoke0(Native Method)
	at sun.reflect.NativeMethodAccessorImpl.invoke(NativeMethodAccessorImpl.java:57)
	at sun.reflect.DelegatingMethodAccessorImpl.invoke(DelegatingMethodAccessorImpl.java:43)
	at java.lang.reflect.Method.invoke(Method.java:606)
	at org.apache.hadoop.io.retry.RetryInvocationHandler.invokeMethod(RetryInvocationHandler.java:190)
	at org.apache.hadoop.io.retry.RetryInvocationHandler.invoke(RetryInvocationHandler.java:103)
	at com.sun.proxy.$Proxy9.getTransactionId(Unknown Source)
	at org.apache.hadoop.hdfs.protocolPB.NamenodeProtocolTranslatorPB.getTransactionID(NamenodeProtocolTranslatorPB.java:119)
	at org.apache.hadoop.hdfs.server.namenode.SecondaryNameNode.countUncheckpointedTxns(SecondaryNameNode.java:621)
	at org.apache.hadoop.hdfs.server.namenode.SecondaryNameNode.shouldCheckpointBasedOnCount(SecondaryNameNode.java:629)
	at org.apache.hadoop.hdfs.server.namenode.SecondaryNameNode.doWork(SecondaryNameNode.java:381)
	at org.apache.hadoop.hdfs.server.namenode.SecondaryNameNode$1.run(SecondaryNameNode.java:349)
	at org.apache.hadoop.security.SecurityUtil.doAsLoginUserOrFatal(SecurityUtil.java:415)
	at org.apache.hadoop.hdfs.server.namenode.SecondaryNameNode.run(SecondaryNameNode.java:345)
	at java.lang.Thread.run(Thread.java:745)
Caused by: java.net.ConnectException: Connection refused
	at sun.nio.ch.SocketChannelImpl.checkConnect(Native Method)
	at sun.nio.ch.SocketChannelImpl.finishConnect(SocketChannelImpl.java:744)
	at org.apache.hadoop.net.SocketIOWithTimeout.connect(SocketIOWithTimeout.java:206)
	at org.apache.hadoop.net.NetUtils.connect(NetUtils.java:529)
	at org.apache.hadoop.net.NetUtils.connect(NetUtils.java:493)
	at org.apache.hadoop.ipc.Client$Connection.setupConnection(Client.java:605)
	at org.apache.hadoop.ipc.Client$Connection.setupIOstreams(Client.java:700)
	at org.apache.hadoop.ipc.Client$Connection.access$2800(Client.java:367)
	at org.apache.hadoop.ipc.Client.getConnection(Client.java:1463)
	at org.apache.hadoop.ipc.Client.call(Client.java:1382)
	... 18 more
java.net.ConnectException: Call From anmol-vm1-new/10.0.1.190 to anmol-vm1-new:8020 failed on connection exception: java.net.ConnectException: Connection refused; For more details see:  http://wiki.apache.org/hadoop/ConnectionRefused
	at sun.reflect.NativeConstructorAccessorImpl.newInstance0(Native Method)
	at sun.reflect.NativeConstructorAccessorImpl.newInstance(NativeConstructorAccessorImpl.java:57)
	at sun.reflect.DelegatingConstructorAccessorImpl.newInstance(DelegatingConstructorAccessorImpl.java:45)
	at java.lang.reflect.Constructor.newInstance(Constructor.java:526)
	at org.apache.hadoop.net.NetUtils.wrapWithMessage(NetUtils.java:783)
	at org.apache.hadoop.net.NetUtils.wrapException(NetUtils.java:730)
	at org.apache.hadoop.ipc.Client.call(Client.java:1415)
	at org.apache.hadoop.ipc.Client.call(Client.java:1364)
	at org.apache.hadoop.ipc.ProtobufRpcEngine$Invoker.invoke(ProtobufRpcEngine.java:206)
	at com.sun.proxy.$Proxy9.getTransactionId(Unknown Source)
	at sun.reflect.NativeMethodAccessorImpl.invoke0(Native Method)
	at sun.reflect.NativeMethodAccessorImpl.invoke(NativeMethodAccessorImpl.java:57)
	at sun.reflect.DelegatingMethodAccessorImpl.invoke(DelegatingMethodAccessorImpl.java:43)
	at java.lang.reflect.Method.invoke(Method.java:606)
	at org.apache.hadoop.io.retry.RetryInvocationHandler.invokeMethod(RetryInvocationHandler.java:190)
	at org.apache.hadoop.io.retry.RetryInvocationHandler.invoke(RetryInvocationHandler.java:103)
	at com.sun.proxy.$Proxy9.getTransactionId(Unknown Source)
	at org.apache.hadoop.hdfs.protocolPB.NamenodeProtocolTranslatorPB.getTransactionID(NamenodeProtocolTranslatorPB.java:119)
	at org.apache.hadoop.hdfs.server.namenode.SecondaryNameNode.countUncheckpointedTxns(SecondaryNameNode.java:621)
	at org.apache.hadoop.hdfs.server.namenode.SecondaryNameNode.shouldCheckpointBasedOnCount(SecondaryNameNode.java:629)
	at org.apache.hadoop.hdfs.server.namenode.SecondaryNameNode.doWork(SecondaryNameNode.java:381)
	at org.apache.hadoop.hdfs.server.namenode.SecondaryNameNode$1.run(SecondaryNameNode.java:349)
	at org.apache.hadoop.security.SecurityUtil.doAsLoginUserOrFatal(SecurityUtil.java:415)
	at org.apache.hadoop.hdfs.server.namenode.SecondaryNameNode.run(SecondaryNameNode.java:345)
	at java.lang.Thread.run(Thread.java:745)
Caused by: java.net.ConnectException: Connection refused
	at sun.nio.ch.SocketChannelImpl.checkConnect(Native Method)
	at sun.nio.ch.SocketChannelImpl.finishConnect(SocketChannelImpl.java:744)
	at org.apache.hadoop.net.SocketIOWithTimeout.connect(SocketIOWithTimeout.java:206)
	at org.apache.hadoop.net.NetUtils.connect(NetUtils.java:529)
	at org.apache.hadoop.net.NetUtils.connect(NetUtils.java:493)
	at org.apache.hadoop.ipc.Client$Connection.setupConnection(Client.java:605)
	at org.apache.hadoop.ipc.Client$Connection.setupIOstreams(Client.java:700)
	at org.apache.hadoop.ipc.Client$Connection.access$2800(Client.java:367)
	at org.apache.hadoop.ipc.Client.getConnection(Client.java:1463)
	at org.apache.hadoop.ipc.Client.call(Client.java:1382)
	... 18 more
